[META]
version=2.0
spawnOnBlockType=12
spawnSunlight=True
spawnDarkness=True
spawnWater=False
spawnLava=False
randomRotation=False
dig=False
rarity=2
spawnInBiome=Desert,DesertOasis
[DATA]
-4,-2,-2:12.0
-3,-2,-2:12.0
-2,-2,-2:12.0
-1,-2,-2:12.0
0,-2,-2:12.0
-4,-1,-2:12.0
-3,-1,-2:24.0
-2,-1,-2:24.0
-1,-1,-2:24.0
0,-1,-2:12.0
-4,0,-2:12.0
-3,0,-2:24.0
-2,0,-2:24.0
-1,0,-2:24.0
0,0,-2:12.0
-4,1,-2:12.0
-3,1,-2:24.0
-2,1,-2:24.0
-1,1,-2:24.0
0,1,-2:12.0
-4,2,-2:12.0
-3,2,-2:24.0
-2,2,-2:24.0
-1,2,-2:24.0
0,2,-2:12.0
-4,3,-2:12.0
-3,3,-2:12.0
-2,3,-2:24.0
-1,3,-2:12.0
0,3,-2:12.0
-4,4,-2:12.0
-3,4,-2:12.0
-2,4,-2:24.0
-1,4,-2:12.0
0,4,-2:12.0
-4,5,-2:12.0
-3,5,-2:12.0
-2,5,-2:12.0
-1,5,-2:12.0
0,5,-2:12.0
-4,6,-2:12.0
-3,6,-2:12.0
-2,6,-2:12.0
-1,6,-2:12.0
0,6,-2:12.0
-4,-2,-1:24.0
-3,-2,-1:24.0
-2,-2,-1:24.0
-1,-2,-1:24.0
0,-2,-1:24.0
-4,-1,-1:24.0
-2,-1,-1:0.0
0,-1,-1:24.0
-4,0,-1:24.0
-2,0,-1:0.0
0,0,-1:24.0
-4,1,-1:24.0
-3,1,-1:0.0
-2,1,-1:0.0
-1,1,-1:0.0
0,1,-1:24.0
-4,2,-1:24.0
-3,2,-1:0.0
-2,2,-1:0.0
-1,2,-1:0.0
0,2,-1:24.0
-4,3,-1:24.0
-3,3,-1:24.0
-1,3,-1:24.0
0,3,-1:24.0
-4,4,-1:12.0
-3,4,-1:24.0
-2,4,-1:0.0
-1,4,-1:24.0
0,4,-1:12.0
-4,5,-1:12.0
-3,5,-1:24.0
-2,5,-1:44.1
-1,5,-1:24.0
0,5,-1:12.0
-4,6,-1:12.0
-3,6,-1:24.0
-2,6,-1:24.0
-1,6,-1:24.0
0,6,-1:12.0
-4,-2,0:24.0
-3,-2,0:24.0
-2,-2,0:24.0
-1,-2,0:24.0
0,-2,0:24.0
-4,-1,0:24.0
-3,-1,0:0.0
-1,-1,0:0.0
0,-1,0:24.0
-4,0,0:24.0
-3,0,0:0.0
-2,0,0:0.0
-1,0,0:0.0
0,0,0:24.0
-4,1,0:24.0
-3,1,0:0.0
-2,1,0:0.0
-1,1,0:0.0
0,1,0:24.0
-4,2,0:24.0
-3,2,0:0.0
-2,2,0:0.0
-1,2,0:0.0
0,2,0:24.0
-4,3,0:24.0
-3,3,0:24.0
-1,3,0:24.0
0,3,0:24.0
-4,4,0:0.0
-3,4,0:44.1
-2,4,0:0.0
-1,4,0:44.1
0,4,0:0.0
-4,5,0:0.0
-3,5,0:0.0
-2,5,0:0.0
-1,5,0:0.0
0,5,0:0.0
-4,6,0:0.0
-3,6,0:0.0
-2,6,0:0.0
-1,6,0:0.0
0,6,0:0.0
-4,-2,1:0.0
-3,-2,1:44.1
-2,-2,1:44.1
-1,-2,1:44.1
0,-2,1:0.0
-4,-1,1:44.1
-3,-1,1:24.0
-2,-1,1:24.0
-1,-1,1:24.0
0,-1,1:44.1
-4,0,1:44.1
-3,0,1:24.0
-2,0,1:0.0
-1,0,1:24.0
0,0,1:44.1
-4,1,1:44.1
-3,1,1:24.0
-2,1,1:0.0
-1,1,1:24.0
0,1,1:44.1
-4,2,1:44.1
-3,2,1:24.0
-2,2,1:24.0
-1,2,1:24.0
0,2,1:44.1
-4,3,1:0.0
-3,3,1:44.1
-2,3,1:44.1
-1,3,1:44.1
0,3,1:0.0
-4,4,1:0.0
-3,4,1:0.0
-2,4,1:0.0
-1,4,1:0.0
0,4,1:0.0
-4,5,1:0.0
-3,5,1:0.0
-2,5,1:0.0
-1,5,1:0.0
0,5,1:0.0
-4,6,1:0.0
-3,6,1:0.0
-2,6,1:0.0
-1,6,1:0.0
0,6,1:0.0
-4,-2,2:0.0
-3,-2,2:0.0
-2,-2,2:0.0
-1,-2,2:0.0
0,-2,2:0.0
-4,-1,2:0.0
-3,-1,2:0.0
-2,-1,2:0.0
-1,-1,2:0.0
0,-1,2:0.0
-4,0,2:0.0
-3,0,2:0.0
-2,0,2:44.1
-1,0,2:0.0
0,0,2:0.0
-4,1,2:0.0
-3,1,2:0.0
-2,1,2:44.1
-1,1,2:0.0
0,1,2:0.0
-4,2,2:0.0
-3,2,2:0.0
-2,2,2:0.0
-1,2,2:0.0
0,2,2:0.0
-4,3,2:0.0
-3,3,2:0.0
-2,3,2:0.0
-1,3,2:0.0
0,3,2:0.0
-4,4,2:0.0
-3,4,2:0.0
-2,4,2:0.0
-1,4,2:0.0
0,4,2:0.0
-4,5,2:0.0
-3,5,2:0.0
-2,5,2:0.0
-1,5,2:0.0
0,5,2:0.0
-4,6,2:0.0
-3,6,2:0.0
-2,6,2:0.0
-1,6,2:0.0
0,6,2:0.0
-2,3,0:64.11
-2,-1,0:50.3
-2,3,-1:64.3
-1,0,-1:26.2
-3,0,-1:26.2
-1,-1,-1:26.10
-3,-1,-1:26.10
