[META]
version=2.0
spawnOnBlockType=12
spawnSunlight=True
spawnDarkness=True
spawnWater=False
spawnLava=False
underFill=True
randomRotation=True
dig=False
tree=False
branch=False
rarity=50
collisionPercentage=25
spawnElevationMin=0
spawnElevationMax=128
spawnInBiome=DesertOasis
[DATA]
0,0,-10:41.0
0,0,-9:8.0
0,0,-8:8.0
0,0,-7:8.0
0,0,-6:8.0
0,0,-5:8.0
0,0,-4:8.0
0,0,-3:8.0
0,0,-2:8.0
0,0,-1:8.0
0,0,0:8.0
-1,-1,0:24.0
-1,0,0:24.0
-1,1,0:24.0
-1,-1,1:85.0
-1,1,1:85.0
-1,-1,2:44.1
-1,0,2:44.1
-1,1,2:44.1
0,-1,0:24.0
0,1,0:24.0
0,-1,2:44.1
0,0,2:44.1
0,1,2:44.1
1,-1,0:24.0
1,0,0:24.0
1,1,0:24.0
1,-1,1:85.0
1,1,1:85.0
1,-1,2:44.1
1,0,2:44.1
1,1,2:44.1
