[META]
version=2.0
spawnOnBlockType=12
spawnSunlight=True
spawnDarkness=False
spawnWater=False
spawnLava=False
underFill=True
randomRotation=True
dig=False
tree=False
branch=False
rarity=1000
collisionPercentage=25
spawnElevationMin=0
spawnElevationMax=128
spawnInBiome=DesertOasis
groupId=PalmTrees
groupFrequencyMin=10
groupFrequencyMax=30
groupSeperationMin=0
groupSeperationMax=5
[DATA]
0,0,0:85
0,0,1:85
0,0,2:85
0,0,3:85
0,0,4:85
0,0,5:17.0
-3,0,5:18.0
0,-3,5:18.0
0,3,5:18.0
3,0,5:18.0
0,0,6:18.0
-1,0,6:18.0
1,0,6:18.0
0,-1,6:18.0
0,1,6:18.0
0,-2,6:18.0
0,2,6:18.0
-2,0,6:18.0
2,0,6:18.0
-1,-1,6:18.0
1,1,6:18.0
-1,1,6:18.0
1,-1,6:18.0
0,-3,6:18.0
0,3,6:18.0
-3,0,6:18.0
3,0,6:18.0
0,0,7:18.0
-2,0,7:18.0
-1,0,7:18.0
0,-2,7:18.0
0,-1,7:18.0
0,1,7:18.0
0,2,7:18.0
1,0,7:18.0
2,0,7:18.0
