[META]
version=2.0
spawnOnBlockType=12
spawnSunlight=True
spawnDarkness=False
spawnWater=False
spawnLava=False
randomRotation=True
dig=False
rarity=1000
spawnInBiome=DesertOasis
groupId=PalmTrees
groupFrequencyMin=10
groupFrequencyMax=30
groupSeperationMin=0
groupSeperationMax=5
[DATA]
0,0,0:85
0,0,1:85
0,0,2:85
0,0,3:85
0,0,4:85
0,0,5:85
0,0,6:85
0,0,7:17.0
1,0,7:178.3
-1,0,7:178.3
0,1,7:178.3
0,-1,7:178.3
-3,0,7:18.0
0,-3,7:18.0
0,3,7:18.0
3,0,7:18.0
0,0,8:18.0
-1,0,8:18.0
1,0,8:18.0
0,-1,8:18.0
0,1,8:18.0
0,-2,8:18.0
0,2,8:18.0
-2,0,8:18.0
2,0,8:18.0
-1,-1,8:18.0
1,1,8:18.0
-1,1,8:18.0
1,-1,8:18.0
0,-3,8:18.0
0,3,8:18.0
-3,0,8:18.0
3,0,8:18.0
0,0,9:18.0
-2,0,9:18.0
-1,0,9:18.0
0,-2,9:18.0
0,-1,9:18.0
0,1,9:18.0
0,2,9:18.0
1,0,9:18.0
2,0,9:18.0
