[META]
version=2.0
spawnOnBlockType=1,2,3
spawnSunlight=True
spawnDarkness=True
spawnWater=False
spawnLava=False
underFill=True
randomRotation=True
dig=True
collisionPercentage=100
rarity=1
spawnInBiome=Jungle,Swamp,HellPlains,HellMountains
[DATA]
-2,-1,-2:98.0
-1,-1,-2:98.0(5),46(1)
0,-1,-2:98.1
-2,0,-2:98.1
-1,0,-2:98.0
0,0,-2:98.0
-2,1,-2:98.1
-1,1,-2:98.1
0,1,-2:98.2
-2,2,-2:98.0
-1,2,-2:98.2
0,2,-2:98.2
-2,-1,-1:98.2
-1,-1,-1:98.2
0,-1,-1:98.1
-2,0,-1:98.0
0,0,-1:98.1
-2,1,-1:98.0
-1,1,-1:0.0
0,1,-1:98.1
-2,2,-1:98.2
-1,2,-1:98.2
0,2,-1:98.1
-2,-1,0:0.0
0,-1,0:0.0
-2,0,0:44.5
-1,0,0:98.0
0,0,0:44.5
-2,1,0:98.2
-1,1,0:98.0
0,1,0:98.0
-2,2,0:98.2
-1,2,0:98.0
0,2,0:98.1
-2,-1,1:0.0
-1,-1,1:0.0
0,-1,1:0.0
-2,0,1:0.0
0,0,1:0.0
-2,1,1:98.2
-1,1,1:41.0,57.0,168.0,168.1,168.2
0,1,1:98.0
-2,2,1:98.0
-1,2,1:98.1
0,2,1:98.1
-2,-1,2:0.0
-1,-1,2:0.0
0,-1,2:0.0
-2,0,2:44.5
-1,0,2:44.5
0,0,2:44.5
-2,1,2:98.1
-1,1,2:98.1
0,1,2:98.1
-2,2,2:98.0
-1,2,2:98.1
0,2,2:98.1
-1,0,1:55.15
-1,-1,0:70.0
-1,0,-1:76.5
