[META]
version=2.0
spawnOnBlockType=1,2,3
spawnSunlight=True
spawnDarkness=True
spawnWater=False
spawnLava=False
underFill=True
randomRotation=False
dig=True
collisionPercentage=100
rarity=1
spawnInBiome=BirchForest,Forest,Jungle,Swamp,SnowyTaiga,Taiga
[DATA]
-1,-3,-2:98.0
0,-3,-2:98.0
1,-3,-2:98.0
-2,-2,-2:98.0
-1,-2,-2:98.0
0,-2,-2:98.0
1,-2,-2:98.0
2,-2,-2:98.0
-3,-1,-2:98.0
-2,-1,-2:98.0
-1,-1,-2:98.0
0,-1,-2:98.1
1,-1,-2:98.1
2,-1,-2:98.0
3,-1,-2:98.0
-3,0,-2:98.0
-2,0,-2:98.0
-1,0,-2:98.0
0,0,-2:98.1
1,0,-2:98.2
2,0,-2:98.0
3,0,-2:98.0
-3,1,-2:98.0
-2,1,-2:98.0
-1,1,-2:98.1
0,1,-2:98.0
1,1,-2:98.2
2,1,-2:98.2
3,1,-2:98.0
-2,2,-2:98.0
-1,2,-2:98.1
0,2,-2:98.0
1,2,-2:98.2
2,2,-2:98.0
-1,3,-2:98.1
0,3,-2:98.1
1,3,-2:98.1
-1,-3,-1:98.0
0,-3,-1:98.0
1,-3,-1:98.2
-2,-2,-1:98.0
-1,-2,-1:98.0
0,-2,-1:98.0
1,-2,-1:98.0
2,-2,-1:98.0
-3,-1,-1:98.1
-2,-1,-1:98.0
-1,-1,-1:98.0
0,-1,-1:98.2
1,-1,-1:98.2
2,-1,-1:98.0
3,-1,-1:98.0
-3,0,-1:98.0
-2,0,-1:98.1
-1,0,-1:98.0
1,0,-1:98.2
2,0,-1:98.2
3,0,-1:98.0
-3,1,-1:98.0
-2,1,-1:98.1
-1,1,-1:98.1
0,1,-1:98.1
1,1,-1:98.0
2,1,-1:98.2
3,1,-1:98.0
-2,2,-1:98.0
-1,2,-1:98.0
0,2,-1:98.1
1,2,-1:98.1
2,2,-1:98.2
-1,3,-1:98.0
0,3,-1:98.1
1,3,-1:98.1
-1,-3,0:98.0
0,-3,0:0.0
1,-3,0:98.2
-2,-2,0:98.2
-1,-2,0:0.0
0,-2,0:0.0
1,-2,0:0.0
2,-2,0:98.2
-3,-1,0:98.1
-2,-1,0:0.0
-1,-1,0:0.0
0,-1,0:0.0
1,-1,0:0.0
2,-1,0:0.0
3,-1,0:98.2
-3,0,0:98.1
-2,0,0:0.0
-1,0,0:0.0
0,0,0:41.0,57.0,168.0,168.1,168.2
1,0,0:0.0
2,0,0:0.0
3,0,0:98.2
-3,1,0:98.0
-2,1,0:0.0
-1,1,0:0.0
0,1,0:0.0
1,1,0:0.0
2,1,0:0.0
3,1,0:98.0
-2,2,0:98.0
-1,2,0:0.0
0,2,0:0.0
1,2,0:0.0
2,2,0:98.2
-1,3,0:98.1
0,3,0:98.1
1,3,0:98.1
-1,-3,1:98.0
0,-3,1:0.0
1,-3,1:98.2
-2,-2,1:98.0
-1,-2,1:0.0
0,-2,1:0.0
1,-2,1:0.0
2,-2,1:98.2
-3,-1,1:98.1
-2,-1,1:0.0
-1,-1,1:0.0
0,-1,1:0.0
1,-1,1:0.0
2,-1,1:0.0
3,-1,1:98.0
-3,0,1:98.0
-1,0,1:0.0
1,0,1:0.0
3,0,1:98.2
-3,1,1:98.0
-2,1,1:0.0
-1,1,1:0.0
0,1,1:0.0
1,1,1:0.0
2,1,1:0.0
3,1,1:98.0
-2,2,1:98.0
-1,2,1:0.0
1,2,1:0.0
2,2,1:98.1
-1,3,1:98.1
0,3,1:98.0
1,3,1:98.1
-1,-3,2:98.0
0,-3,2:98.0
1,-3,2:98.0
-2,-2,2:98.0
-1,-2,2:0.0
0,-2,2:0.0
1,-2,2:0.0
2,-2,2:98.0
-3,-1,2:98.0
-2,-1,2:0.0
-1,-1,2:0.0
0,-1,2:0.0
1,-1,2:0.0
2,-1,2:30.0
3,-1,2:98.0
-3,0,2:98.0
-2,0,2:30.0
-1,0,2:0.0
0,0,2:0.0
1,0,2:0.0
2,0,2:0.0
3,0,2:98.0
-3,1,2:98.0
-2,1,2:30.0
-1,1,2:0.0
0,1,2:0.0
1,1,2:0.0
2,1,2:0.0
3,1,2:98.0
-2,2,2:98.0
-1,2,2:30.0
0,2,2:0.0
1,2,2:0.0
2,2,2:98.2
-1,3,2:98.0
0,3,2:98.0
1,3,2:98.1
-1,-3,3:44.5
0,-3,3:44.5
1,-3,3:44.5
-2,-2,3:44.5
-1,-2,3:98.0
0,-2,3:98.0
1,-2,3:98.0
2,-2,3:44.5
-3,-1,3:44.5
-2,-1,3:98.0
-1,-1,3:0.0
0,-1,3:0.0
1,-1,3:0.0
2,-1,3:98.0
3,-1,3:44.5
-3,0,3:44.5
-2,0,3:98.0
-1,0,3:0.0
0,0,3:0.0
1,0,3:0.0
2,0,3:98.0
3,0,3:44.5
-3,1,3:44.5
-2,1,3:98.0
-1,1,3:30.0
0,1,3:0.0
1,1,3:0.0
2,1,3:98.0
3,1,3:44.5
-2,2,3:44.5
-1,2,3:98.0
0,2,3:98.1
1,2,3:98.1
2,2,3:44.5
-1,3,3:44.5
0,3,3:44.5
1,3,3:44.5
-1,-3,4:0.0
0,-3,4:0.0
1,-3,4:0.0
-1,-2,4:0.0
0,-2,4:0.0
1,-2,4:0.0
-3,-1,4:0.0
-2,-1,4:0.0
-1,-1,4:44.5
0,-1,4:44.5
1,-1,4:44.5
2,-1,4:0.0
3,-1,4:0.0
-3,0,4:0.0
-2,0,4:0.0
-1,0,4:44.5
0,0,4:0.0
1,0,4:44.5
2,0,4:0.0
3,0,4:0.0
-3,1,4:0.0
-2,1,4:0.0
-1,1,4:44.5
0,1,4:44.5
1,1,4:44.5
2,1,4:0.0
3,1,4:0.0
-1,2,4:0.0
0,2,4:0.0
1,2,4:0.0
-1,3,4:0.0
0,3,4:0.0
1,3,4:0.0
0,2,1:76.4
2,0,1:76.2
0,0,1:55.15
-2,0,1:76.1
0,0,-1:76.5
