[META]
version=2.0
spawnOnBlockType=1,2,3
spawnSunlight=True
spawnDarkness=True
spawnWater=False
spawnLava=False
underFill=True
randomRotation=False
dig=False
tree=False
branch=False
rarity=1
collisionPercentage=25
spawnElevationMin=0
spawnElevationMax=128
spawnInBiome=Forest,Taiga
groupId=WheatiesTemple
groupFrequencyMax=1
groupSeperationMin=1000
[DATA]
0,0,0:76.5
0,0,1:41.0
0,0,2:55.0
3,0,0:98.0
3,0,4:98.0
3,0,5:44.5
3,-1,0:4.0
3,-1,1:98.0
3,-1,2:98.0
3,-1,3:98.0
3,-1,4:98.0
3,-1,5:44.5
3,1,0:4.0
3,1,1:98.0
3,1,2:98.0
3,1,3:98.0
3,1,4:98.0
3,1,5:44.5
2,-2,0:4.0
2,-2,1:98.0
2,-2,2:98.0
2,-2,3:98.0
2,-2,4:98.0
2,-2,5:44.5
2,-1,0:98.0
2,-1,5:98.0
2,0,0:98.0
2,0,5:98.0
2,1,0:98.0
2,1,5:98.0
2,2,0:4.0
2,2,1:98.0
2,2,2:98.0
2,2,3:98.0
2,2,4:98.0
2,2,5:44.5
1,-3,0:4.0
1,-3,1:98.0
1,-3,2:98.0
1,-3,3:98.0
1,-3,4:98.0
1,-3,5:44.5
1,-2,0:98.0
1,-2,5:98.0
1,-1,0:98.0
1,-1,6:44.5
1,0,0:98.0
1,0,6:44.5
1,1,0:98.0
1,1,6:44.5
1,2,0:98.0
1,2,4:30.0
1,2,5:98.0
1,3,0:4.0
1,3,1:98.0
1,3,2:98.0
1,3,3:98.0
1,3,4:98.0
1,3,5:44.5
0,-3,0:4.0
0,-3,1:98.0
0,-3,2:98.0
0,-3,3:98.0
0,-3,4:98.0
0,-3,5:44.5
0,-2,0:98.0
0,-2,4:30.0
0,-2,5:98.0
0,-1,0:98.0
0,-1,6:44.5
0,1,0:98.0
0,1,6:44.5
0,2,0:98.0
0,2,5:98.0
0,3,0:4.0
0,3,1:98.0
0,3,2:98.0
0,3,3:98.0
0,3,4:98.0
0,3,5:44.5
-1,-3,0:4.0
-1,-3,1:98.0
-1,-3,2:98.0
-1,-3,3:98.0
-1,-3,4:98.0
-1,-3,5:44.5
-1,-2,0:98.0
-1,-2,4:30.0
-1,-2,5:98.0
-1,-1,0:98.0
-1,-1,5:30.0
-1,-1,6:44.5
-1,0,0:98.0
-1,0,6:44.5
-1,1,0:98.0
-1,1,6:44.5
-1,2,0:98.0
-1,2,5:98.0
-1,3,0:4.0
-1,3,1:98.0
-1,3,2:98.0
-1,3,3:98.0
-1,3,4:98.0
-1,3,5:44.5
-2,-2,0:4.0
-2,-2,1:98.0
-2,-2,2:98.0
-2,-2,3:98.0
-2,-2,4:98.0
-2,-2,5:44.5
-2,-1,0:98.0
-2,-1,5:98.0
-2,0,0:98.0
-2,0,5:98.0
-2,1,0:98.0
-2,1,5:98.0
-2,2,0:4.0
-2,2,1:98.0
-2,2,2:98.0
-2,2,3:98.0
-2,2,4:98.0
-2,2,5:44.5
-3,0,0:98.0
-3,0,1:98.0
-3,0,2:98.0
-3,0,3:98.0
-3,0,4:98.0
-3,0,5:44.5
-3,-1,0:4.0
-3,-1,1:98.0
-3,-1,2:98.0
-3,-1,3:98.0
-3,-1,4:98.0
-3,-1,5:44.5
-3,1,0:4.0
-3,1,1:98.0
-3,1,2:98.0
-3,1,3:98.0
-3,1,4:98.0
-3,1,5:44.5
0,2,2:76.4
0,-2,2:76.3
-2,0,2:76.1
-3,-1,-1:4.0
-3,0,-1:4.0
-3,1,-1:4.0
-2,-2,-1:4.0
-2,2,-1:4.0
-1,-3,-1:4.0
-1,3,-1:4.0
0,-3,-1:4.0
0,3,-1:4.0
1,-3,-1:4.0
1,3,-1:4.0
2,-2,-1:4.0
2,2,-1:4.0
3,-1,-1:4.0
3,0,-1:4.0
3,1,-1:4.0
