[META]
version=2.0
spawnOnBlockType=1,2,3
spawnSunlight=True
spawnDarkness=True
spawnWater=False
spawnLava=False
randomRotation=True
dig=False
spawnInBiome=WoolIsland
groupId=WoolTree
rarity=500
groupFrequencyMin=3
groupFrequencyMax=100
groupSeperationMin=6
groupSeperationMax=16
[DATA]
0,0,0:35.12
0,0,1:35.12
0,0,2:35.12
-2,-2,3:35.5
-1,-2,3:35.5
0,-2,3:35.5
1,-2,3:35.5
-2,-1,3:35.5
-1,-1,3:35.5
0,-1,3:35.5
1,-1,3:35.5
2,-1,3:35.5
-2,0,3:35.5
-1,0,3:35.5
0,0,3:35.12
1,0,3:35.5
2,0,3:35.5
-2,1,3:35.5
-1,1,3:35.5
0,1,3:35.5
1,1,3:35.5
2,1,3:35.5
-1,2,3:35.5
0,2,3:35.5
1,2,3:35.5
2,2,3:35.5
-1,-2,4:35.5
0,-2,4:35.5
1,-2,4:35.5
-2,-1,4:35.5
-1,-1,4:35.5
0,-1,4:35.5
1,-1,4:35.5
2,-1,4:35.5
-2,0,4:35.5
-1,0,4:35.5
0,0,4:35.12
1,0,4:35.5
2,0,4:35.5
-2,1,4:35.5
-1,1,4:35.5
0,1,4:35.5
1,1,4:35.5
2,1,4:35.5
-1,2,4:35.5
0,2,4:35.5
1,2,4:35.5
2,2,4:35.5
-1,-1,5:35.5
0,-1,5:35.5
-1,0,5:35.5
0,0,5:35.12
1,0,5:35.5
0,1,5:35.5
1,1,5:35.5
0,-1,6:35.5
-1,0,6:35.5
0,0,6:35.5
1,0,6:35.5
0,1,6:35.5
